Workbook

Sheet 线路
A1: 支路 | B1: 起点 | C1: 终点 | D1: 电阻 | E1: 电抗 | F1: 长度(km) | G1: 单位电阻 | H1: 单位电抗 | I1: 线路容量(kW) | J1: 所属馈线 | N1: 线路直径 D (单位: mm)
A2: 1 | B2: 1 | C2: 2 | D2: =F2*G2 -> 0.057465031 | E2: =F2*H2 -> 0.15411076 | F2: =SQRT((VLOOKUP(B2,节点!A:E,4,0)-VLOOKUP(C2,节点!A:E,4,0))^2+(VLOOKUP(B2,节点!A:E,5,0)-VLOOKUP(C2,节点!A:E,5,0))^2)/基准点!$F$1 -> 0.43534114 | G2: 0.132 | H2: 0.354 | I2: 9890 | J2: 雷6板(提灌)线240/5.45/9890/0.92/15% | K2: 240 | M2: =_xlfn.CONCAT(B2,"-",C2) -> 1-2 | N2: =SQRT(4*K2/PI()) -> 17.480775
A3: 2 | B3: 2 | C3: 3 | D3: =F3*G3 -> 0.077706532 | E3: =F3*H3 -> 0.20839479 | F3: =SQRT((VLOOKUP(B3,节点!A:E,4,0)-VLOOKUP(C3,节点!A:E,4,0))^2+(VLOOKUP(B3,节点!A:E,5,0)-VLOOKUP(C3,节点!A:E,5,0))^2)/基准点!$F$1 -> 0.58868585 | G3: 0.132 | H3: 0.354 | I3: 9890 | K3: 240 | M3: =_xlfn.CONCAT(B3,"-",C3) -> 2-3 | N3: =SQRT(4*K3/PI()) -> 17.480775
A4: 3 | B4: 3 | C4: 4 | D4: =F4*G4 -> 0.5087128 | E4: =F4*H4 -> 1.3642752 | F4: =SQRT((VLOOKUP(B4,节点!A:E,4,0)-VLOOKUP(C4,节点!A:E,4,0))^2+(VLOOKUP(B4,节点!A:E,5,0)-VLOOKUP(C4,节点!A:E,5,0))^2)/基准点!$F$1 -> 3.8538848 | G4: 0.132 | H4: 0.354 | I4: 9890 | K4: 240 | M4: =_xlfn.CONCAT(B4,"-",C4) -> 3-4 | N4: =SQRT(4*K4/PI()) -> 17.480775
A5: 4 | B5: 1 | C5: 5 | D5: =F5*G5 -> 0.19265548 | E5: =F5*H5 -> 0.41364264 | F5: =SQRT((VLOOKUP(B5,节点!A:E,4,0)-VLOOKUP(C5,节点!A:E,4,0))^2+(VLOOKUP(B5,节点!A:E,5,0)-VLOOKUP(C5,节点!A:E,5,0))^2)/基准点!$F$1 -> 1.1332675 | G5: 0.17 | H5: 0.365 | I5: 34670.4 | J5: 雷7板(朱庄)线185/6.14/34670.4/0.48/6% | K5: 185 | M5: =_xlfn.CONCAT(B5,"-",C5) -> 1-5 | N5: =SQRT(4*K5/PI()) -> 15.347616
A6: 5 | B6: 5 | C6: 6 | D6: =F6*G6 -> 0.4294721 | E6: =F6*H6 -> 0.92210185 | F6: =SQRT((VLOOKUP(B6,节点!A:E,4,0)-VLOOKUP(C6,节点!A:E,4,0))^2+(VLOOKUP(B6,节点!A:E,5,0)-VLOOKUP(C6,节点!A:E,5,0))^2)/基准点!$F$1 -> 2.5263064 | G6: 0.17 | H6: 0.365 | I6: 34670.4 | K6: 185 | M6: =_xlfn.CONCAT(B6,"-",C6) -> 5-6 | N6: =SQRT(4*K6/PI()) -> 15.347616
A7: 6 | B7: 6 | C7: 7 | D7: =F7*G7 -> 0.73382472 | E7: =F7*H7 -> 1.5755648 | F7: =SQRT((VLOOKUP(B7,节点!A:E,4,0)-VLOOKUP(C7,节点!A:E,4,0))^2+(VLOOKUP(B7,节点!A:E,5,0)-VLOOKUP(C7,节点!A:E,5,0))^2)/基准点!$F$1 -> 4.316616 | G7: 0.17 | H7: 0.365 | I7: 34670.4 | K7: 185 | M7: =_xlfn.CONCAT(B7,"-",C7) -> 6-7 | N7: =SQRT(4*K7/PI()) -> 15.347616
A8: 7 | B8: 1 | C8: 8 | D8: =F8*G8 -> 0.061906353 | E8: =F8*H8 -> 0.16602158 | F8: =SQRT((VLOOKUP(B8,节点!A:E,4,0)-VLOOKUP(C8,节点!A:E,4,0))^2+(VLOOKUP(B8,节点!A:E,5,0)-VLOOKUP(C8,节点!A:E,5,0))^2)/基准点!$F$1 -> 0.46898752 | G8: 0.132 | H8: 0.354 | I8: 7615.4 | J8: 雷3板(坝直)线240/2.9/7615.4/2.58/42% | K8: 240 | M8: =_xlfn.CONCAT(B8,"-",C8) -> 1-8 | N8: =SQRT(4*K8/PI()) -> 17.480775
A9: 8 | B9: 8 | C9: 9 | D9: =F9*G9 -> 0.078244608 | E9: =F9*H9 -> 0.20983781 | F9: =SQRT((VLOOKUP(B9,节点!A:E,4,0)-VLOOKUP(C9,节点!A:E,4,0))^2+(VLOOKUP(B9,节点!A:E,5,0)-VLOOKUP(C9,节点!A:E,5,0))^2)/基准点!$F$1 -> 0.59276218 | G9: 0.132 | H9: 0.354 | I9: 7615.4 | K9: 240 | M9: =_xlfn.CONCAT(B9,"-",C9) -> 8-9 | N9: =SQRT(4*K9/PI()) -> 17.480775
A10: 9 | B10: 1 | C10: 10 | D10: =F10*G10 -> 0.71235725 | E10: =F10*H10 -> 1.5294729 | F10: =SQRT((VLOOKUP(B10,节点!A:E,4,0)-VLOOKUP(C10,节点!A:E,4,0))^2+(VLOOKUP(B10,节点!A:E,5,0)-VLOOKUP(C10,节点!A:E,5,0))^2)/基准点!$F$1 -> 4.1903368 | G10: 0.17 | H10: 0.365 | I10: 14951.6 | J10: 雷8板(北滩)线185/12.5/14951.6/0.59/14.1% | K10: 185 | M10: =_xlfn.CONCAT(B10,"-",C10) -> 1-10 | N10: =SQRT(4*K10/PI()) -> 15.347616
A11: 10 | B11: 10 | C11: 11 | D11: =F11*G11 -> 0.58814702 | E11: =F11*H11 -> 1.2627862 | F11: =SQRT((VLOOKUP(B11,节点!A:E,4,0)-VLOOKUP(C11,节点!A:E,4,0))^2+(VLOOKUP(B11,节点!A:E,5,0)-VLOOKUP(C11,节点!A:E,5,0))^2)/基准点!$F$1 -> 3.4596883 | G11: 0.17 | H11: 0.365 | I11: 14951.6 | K11: 185 | M11: =_xlfn.CONCAT(B11,"-",C11) -> 10-11 | N11: =SQRT(4*K11/PI()) -> 15.347616
A12: 11 | B12: 10 | C12: 12 | D12: =F12*G12 -> 0.25615459 | E12: =F12*H12 -> 0.54997897 | F12: =SQRT((VLOOKUP(B12,节点!A:E,4,0)-VLOOKUP(C12,节点!A:E,4,0))^2+(VLOOKUP(B12,节点!A:E,5,0)-VLOOKUP(C12,节点!A:E,5,0))^2)/基准点!$F$1 -> 1.5067917 | G12: 0.17 | H12: 0.365 | I12: 14951.6 | K12: 185 | M12: =_xlfn.CONCAT(B12,"-",C12) -> 10-12 | N12: =SQRT(4*K12/PI()) -> 15.347616
A13: 12 | B13: 12 | C13: 13 | D13: =F13*G13 -> 0.60436533 | E13: =F13*H13 -> 1.2976079 | F13: =SQRT((VLOOKUP(B13,节点!A:E,4,0)-VLOOKUP(C13,节点!A:E,4,0))^2+(VLOOKUP(B13,节点!A:E,5,0)-VLOOKUP(C13,节点!A:E,5,0))^2)/基准点!$F$1 -> 3.5550902 | G13: 0.17 | H13: 0.365 | I13: 14951.6 | K13: 185 | M13: =_xlfn.CONCAT(B13,"-",C13) -> 12-13 | N13: =SQRT(4*K13/PI()) -> 15.347616
A14: 13 | B14: 1 | C14: 14 | D14: =F14*G14 -> 0.21990887 | E14: =F14*H14 -> 0.5897556 | F14: =SQRT((VLOOKUP(B14,节点!A:E,4,0)-VLOOKUP(C14,节点!A:E,4,0))^2+(VLOOKUP(B14,节点!A:E,5,0)-VLOOKUP(C14,节点!A:E,5,0))^2)/基准点!$F$1 -> 1.6659763 | G14: 0.132 | H14: 0.354 | I14: 18961.4 | J14: 雷2板(长胜)线240/6.98/18961.4/3.77/61.2% | K14: 240 | M14: =_xlfn.CONCAT(B14,"-",C14) -> 1-14 | N14: =SQRT(4*K14/PI()) -> 17.480775
A15: 14 | B15: 14 | C15: 15 | D15: =F15*G15 -> 0.24948527 | E15: =F15*H15 -> 0.66907414 | F15: =SQRT((VLOOKUP(B15,节点!A:E,4,0)-VLOOKUP(C15,节点!A:E,4,0))^2+(VLOOKUP(B15,节点!A:E,5,0)-VLOOKUP(C15,节点!A:E,5,0))^2)/基准点!$F$1 -> 1.89004 | G15: 0.132 | H15: 0.354 | I15: 18961.4 | K15: 240 | M15: =_xlfn.CONCAT(B15,"-",C15) -> 14-15 | N15: =SQRT(4*K15/PI()) -> 17.480775
A16: 15 | B16: 15 | C16: 16 | D16: =F16*G16 -> 0.21120252 | E16: =F16*H16 -> 0.56640675 | F16: =SQRT((VLOOKUP(B16,节点!A:E,4,0)-VLOOKUP(C16,节点!A:E,4,0))^2+(VLOOKUP(B16,节点!A:E,5,0)-VLOOKUP(C16,节点!A:E,5,0))^2)/基准点!$F$1 -> 1.6000191 | G16: 0.132 | H16: 0.354 | I16: 18961.4 | K16: 240 | M16: =_xlfn.CONCAT(B16,"-",C16) -> 15-16 | N16: =SQRT(4*K16/PI()) -> 17.480775
A17: 16 | B17: 15 | C17: 17 | D17: =F17*G17 -> 0.23328487 | E17: =F17*H17 -> 0.62562761 | F17: =SQRT((VLOOKUP(B17,节点!A:E,4,0)-VLOOKUP(C17,节点!A:E,4,0))^2+(VLOOKUP(B17,节点!A:E,5,0)-VLOOKUP(C17,节点!A:E,5,0))^2)/基准点!$F$1 -> 1.7673096 | G17: 0.132 | H17: 0.354 | I17: 18961.4 | K17: 240 | M17: =_xlfn.CONCAT(B17,"-",C17) -> 15-17 | N17: =SQRT(4*K17/PI()) -> 17.480775
A18: 17 | B18: 18 | C18: 19 | D18: =F18*G18 -> 0.11028921 | E18: =F18*H18 -> 0.29577562 | F18: =SQRT((VLOOKUP(B18,节点!A:E,4,0)-VLOOKUP(C18,节点!A:E,4,0))^2+(VLOOKUP(B18,节点!A:E,5,0)-VLOOKUP(C18,节点!A:E,5,0))^2)/基准点!$F$1 -> 0.83552435 | G18: 0.132 | H18: 0.354 | I18: 33600 | J18: 爪16板(谷营)线240/14.9/33600/7.41/93.8% | K18: 240 | M18: =_xlfn.CONCAT(B18,"-",C18) -> 18-19 | N18: =SQRT(4*K18/PI()) -> 17.480775
A19: 18 | B19: 19 | C19: 20 | D19: =F19*G19 -> 0.16282078 | E19: =F19*H19 -> 0.43665573 | F19: =SQRT((VLOOKUP(B19,节点!A:E,4,0)-VLOOKUP(C19,节点!A:E,4,0))^2+(VLOOKUP(B19,节点!A:E,5,0)-VLOOKUP(C19,节点!A:E,5,0))^2)/基准点!$F$1 -> 1.2334908 | G19: 0.132 | H19: 0.354 | I19: 33600 | K19: 240 | M19: =_xlfn.CONCAT(B19,"-",C19) -> 19-20 | N19: =SQRT(4*K19/PI()) -> 17.480775
A20: 19 | B20: 20 | C20: 21 | D20: =F20*G20 -> 0.11026261 | E20: =F20*H20 -> 0.29570427 | F20: =SQRT((VLOOKUP(B20,节点!A:E,4,0)-VLOOKUP(C20,节点!A:E,4,0))^2+(VLOOKUP(B20,节点!A:E,5,0)-VLOOKUP(C20,节点!A:E,5,0))^2)/基准点!$F$1 -> 0.8353228 | G20: 0.132 | H20: 0.354 | I20: 33600 | K20: 240 | M20: =_xlfn.CONCAT(B20,"-",C20) -> 20-21 | N20: =SQRT(4*K20/PI()) -> 17.480775
A21: 20 | B21: 20 | C21: 22 | D21: =F21*G21 -> 0.1910089 | E21: =F21*H21 -> 0.51225115 | F21: =SQRT((VLOOKUP(B21,节点!A:E,4,0)-VLOOKUP(C21,节点!A:E,4,0))^2+(VLOOKUP(B21,节点!A:E,5,0)-VLOOKUP(C21,节点!A:E,5,0))^2)/基准点!$F$1 -> 1.4470371 | G21: 0.132 | H21: 0.354 | I21: 33600 | K21: 240 | M21: =_xlfn.CONCAT(B21,"-",C21) -> 20-22 | N21: =SQRT(4*K21/PI()) -> 17.480775
A22: 21 | B22: 22 | C22: 23 | D22: =F22*G22 -> 0.22977939 | E22: =F22*H22 -> 0.61622655 | F22: =SQRT((VLOOKUP(B22,节点!A:E,4,0)-VLOOKUP(C22,节点!A:E,4,0))^2+(VLOOKUP(B22,节点!A:E,5,0)-VLOOKUP(C22,节点!A:E,5,0))^2)/基准点!$F$1 -> 1.740753 | G22: 0.132 | H22: 0.354 | I22: 33600 | K22: 240 | M22: =_xlfn.CONCAT(B22,"-",C22) -> 22-23 | N22: =SQRT(4*K22/PI()) -> 17.480775
A23: 22 | B23: 22 | C23: 24 | D23: =F23*G23 -> 0.11394503 | E23: =F23*H23 -> 0.30557987 | F23: =SQRT((VLOOKUP(B23,节点!A:E,4,0)-VLOOKUP(C23,节点!A:E,4,0))^2+(VLOOKUP(B23,节点!A:E,5,0)-VLOOKUP(C23,节点!A:E,5,0))^2)/基准点!$F$1 -> 0.86321996 | G23: 0.132 | H23: 0.354 | I23: 33600 | K23: 240 | M23: =_xlfn.CONCAT(B23,"-",C23) -> 22-24 | N23: =SQRT(4*K23/PI()) -> 17.480775
A24: 23 | B24: 24 | C24: 25 | D24: =F24*G24 -> 0.13941614 | E24: =F24*H24 -> 0.37388873 | F24: =SQRT((VLOOKUP(B24,节点!A:E,4,0)-VLOOKUP(C24,节点!A:E,4,0))^2+(VLOOKUP(B24,节点!A:E,5,0)-VLOOKUP(C24,节点!A:E,5,0))^2)/基准点!$F$1 -> 1.0561828 | G24: 0.132 | H24: 0.354 | I24: 33600 | K24: 240 | M24: =_xlfn.CONCAT(B24,"-",C24) -> 24-25 | N24: =SQRT(4*K24/PI()) -> 17.480775
A25: 24 | B25: 25 | C25: 26 | D25: =F25*G25 -> 0.14312995 | E25: =F25*H25 -> 0.38384849 | F25: =SQRT((VLOOKUP(B25,节点!A:E,4,0)-VLOOKUP(C25,节点!A:E,4,0))^2+(VLOOKUP(B25,节点!A:E,5,0)-VLOOKUP(C25,节点!A:E,5,0))^2)/基准点!$F$1 -> 1.0843178 | G25: 0.132 | H25: 0.354 | I25: 33600 | K25: 240 | M25: =_xlfn.CONCAT(B25,"-",C25) -> 25-26 | N25: =SQRT(4*K25/PI()) -> 17.480775
A26: 25 | B26: 26 | C26: 27 | D26: =F26*G26 -> 0.32253329 | E26: =F26*H26 -> 0.86497565 | F26: =SQRT((VLOOKUP(B26,节点!A:E,4,0)-VLOOKUP(C26,节点!A:E,4,0))^2+(VLOOKUP(B26,节点!A:E,5,0)-VLOOKUP(C26,节点!A:E,5,0))^2)/基准点!$F$1 -> 2.443434 | G26: 0.132 | H26: 0.354 | I26: 33600 | K26: 240 | M26: =_xlfn.CONCAT(B26,"-",C26) -> 26-27 | N26: =SQRT(4*K26/PI()) -> 17.480775
A27: 26 | B27: 26 | C27: 28 | D27: =F27*G27 -> 0.72953385 | E27: =F27*H27 -> 0.85333354 | F27: =SQRT((VLOOKUP(B27,节点!A:E,4,0)-VLOOKUP(C27,节点!A:E,4,0))^2+(VLOOKUP(B27,节点!A:E,5,0)-VLOOKUP(C27,节点!A:E,5,0))^2)/基准点!$F$1 -> 2.2107086 | G27: 0.33 | H27: 0.386 | I27: 36705 | J27: 张集抗早支线85/7.44/36705 | K27: 85 | M27: =_xlfn.CONCAT(B27,"-",C27) -> 26-28 | N27: =SQRT(4*K27/PI()) -> 10.403142
A28: 27 | B28: 28 | C28: 29 | D28: =F28*G28 -> 1.7774881 | E28: =F28*H28 -> 2.0791224 | F28: =SQRT((VLOOKUP(B28,节点!A:E,4,0)-VLOOKUP(C28,节点!A:E,4,0))^2+(VLOOKUP(B28,节点!A:E,5,0)-VLOOKUP(C28,节点!A:E,5,0))^2)/基准点!$F$1 -> 5.3863274 | G28: 0.33 | H28: 0.386 | I28: 36705 | K28: 85 | M28: =_xlfn.CONCAT(B28,"-",C28) -> 28-29 | N28: =SQRT(4*K28/PI()) -> 10.403142
A29: 28 | B29: 18 | C29: 30 | D29: =F29*G29 -> 0.09548851 | E29: =F29*H29 -> 0.25608282 | F29: =SQRT((VLOOKUP(B29,节点!A:E,4,0)-VLOOKUP(C29,节点!A:E,4,0))^2+(VLOOKUP(B29,节点!A:E,5,0)-VLOOKUP(C29,节点!A:E,5,0))^2)/基准点!$F$1 -> 0.7233978 | G29: 0.132 | H29: 0.354 | I29: 12717.2 | J29: 爪15板(中明)线240/5.8/12717.2/2.55/32.3% | K29: 240 | M29: =_xlfn.CONCAT(B29,"-",C29) -> 18-30 | N29: =SQRT(4*K29/PI()) -> 17.480775
A30: 29 | B30: 30 | C30: 31 | D30: =F30*G30 -> 0.12106669 | E30: =F30*H30 -> 0.32467884 | F30: =SQRT((VLOOKUP(B30,节点!A:E,4,0)-VLOOKUP(C30,节点!A:E,4,0))^2+(VLOOKUP(B30,节点!A:E,5,0)-VLOOKUP(C30,节点!A:E,5,0))^2)/基准点!$F$1 -> 0.91717187 | G30: 0.132 | H30: 0.354 | I30: 12717.2 | K30: 240 | M30: =_xlfn.CONCAT(B30,"-",C30) -> 30-31 | N30: =SQRT(4*K30/PI()) -> 17.480775
A31: 30 | B31: 31 | C31: 32 | D31: =F31*G31 -> 0.29254477 | E31: =F31*H31 -> 0.78455188 | F31: =SQRT((VLOOKUP(B31,节点!A:E,4,0)-VLOOKUP(C31,节点!A:E,4,0))^2+(VLOOKUP(B31,节点!A:E,5,0)-VLOOKUP(C31,节点!A:E,5,0))^2)/基准点!$F$1 -> 2.2162483 | G31: 0.132 | H31: 0.354 | I31: 12717.2 | K31: 240 | M31: =_xlfn.CONCAT(B31,"-",C31) -> 31-32 | N31: =SQRT(4*K31/PI()) -> 17.480775
A32: 31 | B32: 32 | C32: 33 | D32: =F32*G32 -> 0.18811087 | E32: =F32*H32 -> 0.50447915 | F32: =SQRT((VLOOKUP(B32,节点!A:E,4,0)-VLOOKUP(C32,节点!A:E,4,0))^2+(VLOOKUP(B32,节点!A:E,5,0)-VLOOKUP(C32,节点!A:E,5,0))^2)/基准点!$F$1 -> 1.4250823 | G32: 0.132 | H32: 0.354 | I32: 12717.2 | K32: 240 | M32: =_xlfn.CONCAT(B32,"-",C32) -> 32-33 | N32: =SQRT(4*K32/PI()) -> 17.480775
A33: 32 | B33: 33 | C33: 34 | D33: =F33*G33 -> 0.12819726 | E33: =F33*H33 -> 0.34380175 | F33: =SQRT((VLOOKUP(B33,节点!A:E,4,0)-VLOOKUP(C33,节点!A:E,4,0))^2+(VLOOKUP(B33,节点!A:E,5,0)-VLOOKUP(C33,节点!A:E,5,0))^2)/基准点!$F$1 -> 0.9711914 | G33: 0.132 | H33: 0.354 | I33: 12717.2 | K33: 240 | M33: =_xlfn.CONCAT(B33,"-",C33) -> 33-34 | N33: =SQRT(4*K33/PI()) -> 17.480775
A34: 33 | B34: 18 | C34: 35 | D34: =F34*G34 -> 0.32518876 | E34: =F34*H34 -> 0.87209712 | F34: =SQRT((VLOOKUP(B34,节点!A:E,4,0)-VLOOKUP(C34,节点!A:E,4,0))^2+(VLOOKUP(B34,节点!A:E,5,0)-VLOOKUP(C34,节点!A:E,5,0))^2)/基准点!$F$1 -> 2.4635512 | G34: 0.132 | H34: 0.354 | I34: 24420 | J34: 爪5板(马目)线240/5.9/24420/4.85/61.4% | K34: 240 | M34: =_xlfn.CONCAT(B34,"-",C34) -> 18-35 | N34: =SQRT(4*K34/PI()) -> 17.480775
A35: 34 | B35: 35 | C35: 36 | D35: =F35*G35 -> 0.11074922 | E35: =F35*H35 -> 0.29700928 | F35: =SQRT((VLOOKUP(B35,节点!A:E,4,0)-VLOOKUP(C35,节点!A:E,4,0))^2+(VLOOKUP(B35,节点!A:E,5,0)-VLOOKUP(C35,节点!A:E,5,0))^2)/基准点!$F$1 -> 0.83900927 | G35: 0.132 | H35: 0.354 | I35: 24420 | K35: 240 | M35: =_xlfn.CONCAT(B35,"-",C35) -> 35-36 | N35: =SQRT(4*K35/PI()) -> 17.480775
A36: 35 | B36: 36 | C36: 37 | D36: =F36*G36 -> 0.21906638 | E36: =F36*H36 -> 0.58749619 | F36: =SQRT((VLOOKUP(B36,节点!A:E,4,0)-VLOOKUP(C36,节点!A:E,4,0))^2+(VLOOKUP(B36,节点!A:E,5,0)-VLOOKUP(C36,节点!A:E,5,0))^2)/基准点!$F$1 -> 1.6595938 | G36: 0.132 | H36: 0.354 | I36: 24420 | K36: 240 | M36: =_xlfn.CONCAT(B36,"-",C36) -> 36-37 | N36: =SQRT(4*K36/PI()) -> 17.480775
A37: 36 | B37: 18 | C37: 38 | D37: =F37*G37 -> 0.40164116 | E37: =F37*H37 -> 0.86234721 | F37: =SQRT((VLOOKUP(B37,节点!A:E,4,0)-VLOOKUP(C37,节点!A:E,4,0))^2+(VLOOKUP(B37,节点!A:E,5,0)-VLOOKUP(C37,节点!A:E,5,0))^2)/基准点!$F$1 -> 2.3625951 | G37: 0.17 | H37: 0.365 | I37: 23751 | J37: 爪14板(爪营)线185/9.8/23751/5.2/65.9% | K37: 185 | M37: =_xlfn.CONCAT(B37,"-",C37) -> 18-38 | N37: =SQRT(4*K37/PI()) -> 15.347616
A38: 37 | B38: 38 | C38: 39 | D38: =F38*G38 -> 0.35722142 | E38: =F38*H38 -> 0.76697541 | F38: =SQRT((VLOOKUP(B38,节点!A:E,4,0)-VLOOKUP(C38,节点!A:E,4,0))^2+(VLOOKUP(B38,节点!A:E,5,0)-VLOOKUP(C38,节点!A:E,5,0))^2)/基准点!$F$1 -> 2.1013025 | G38: 0.17 | H38: 0.365 | I38: 23751 | K38: 185 | M38: =_xlfn.CONCAT(B38,"-",C38) -> 38-39 | N38: =SQRT(4*K38/PI()) -> 15.347616
A39: 38 | B39: 39 | C39: 40 | D39: =F39*G39 -> 0.060418063 | E39: =F39*H39 -> 0.16203026 | F39: =SQRT((VLOOKUP(B39,节点!A:E,4,0)-VLOOKUP(C39,节点!A:E,4,0))^2+(VLOOKUP(B39,节点!A:E,5,0)-VLOOKUP(C39,节点!A:E,5,0))^2)/基准点!$F$1 -> 0.4577126 | G39: 0.132 | H39: 0.354 | I39: 32580 | J39: 程场支线240/7.57/32580 | K39: 240 | M39: =_xlfn.CONCAT(B39,"-",C39) -> 39-40 | N39: =SQRT(4*K39/PI()) -> 17.480775
A40: 39 | B40: 40 | C40: 41 | D40: =F40*G40 -> 0.4127866 | E40: =F40*H40 -> 1.1070186 | F40: =SQRT((VLOOKUP(B40,节点!A:E,4,0)-VLOOKUP(C40,节点!A:E,4,0))^2+(VLOOKUP(B40,节点!A:E,5,0)-VLOOKUP(C40,节点!A:E,5,0))^2)/基准点!$F$1 -> 3.1271712 | G40: 0.132 | H40: 0.354 | I40: 32580 | K40: 240 | M40: =_xlfn.CONCAT(B40,"-",C40) -> 40-41 | N40: =SQRT(4*K40/PI()) -> 17.480775
...

Sheet 节点
A1: 雷集变负荷 | B1: =SQRT(SUM(B4:B20)^2+SUM(C4:C20)^2) -> 8176.4145
A2: 爪营变负荷 | B2: =SQRT(SUM(B21:B49)^2+SUM(C21:C49)^2) -> 36451.708
A3: 节点 | B3: 有功 | C3: 无功 | D3: X | E3: Y | F3: 所属馈线 | G3: 馈线负荷占比 | H3: 功率因数 | I3: 馈线容量 | J3: 最大负载率 | K3: 负荷修正系数 | L3: 有功占比随机数 | M3: 4 | N3: {=_xlfn.LET(_xlpm.n,$M$3,_xlpm.r,_xlfn.RANDARRAY(_xlpm.n,1),_xlpm.s,_xlpm.r/SUM(_xlpm.r),_xlfn._xlws.SORT(_xlpm.s,1,-1))} -> 0.31758145
A4: 1 | B4: =I4*J4*G4*H4*K4 -> 0 | C4: =0.15*9890*G4*SQRT(1-H4^2)*K4 -> 0 | D4: 99.265 | E4: 319.446 | F4: - | G4: 0 | H4: 0.74032618 | I4: 0 | J4: 0 | K4: 0.5 | L4: =0.7+(0.9-0.7)*RAND() -> 0.72873956 | N4: 0.3106345
A5: 2 | B5: =I5*J5*G5*H5*K5 -> 215.42311 | C5: =0.15*9890*G5*SQRT(1-H5^2)*K5 -> 197.36148 | D5: 90.993 | E5: 315.375 | F5: 雷6板(提灌)线240/5.45/9890/0.92/15% | G5: 0.39388212 | H5: 0.73734114 | I5: 9890 | J5: 0.15 | K5: 0.5 | L5: =0.7+(0.9-0.7)*RAND() -> 0.76009867 | N5: 0.20579132
A6: 3 | B6: =I6*J6*G6*H6*K6 -> 207.45209 | C6: =0.15*9890*G6*SQRT(1-H6^2)*K6 -> 160.80153 | D6: 84.463 | E6: 304.755 | G6: 0.35386008 | H6: 0.79036681 | I6: 9890 | J6: 0.15 | K6: 0.5 | L6: =0.7+(0.9-0.7)*RAND() -> 0.75140371 | N6: 0.16599273
A7: 4 | B7: =I7*J7*G7*H7*K7 -> 152.71962 | C7: =0.15*9890*G7*SQRT(1-H7^2)*K7 -> 108.10967 | D7: 120.466 | E7: 231.509 | G7: 0.2522578 | H7: 0.81619266 | I7: 9890 | J7: 0.15 | K7: 0.5 | L7: =0.7+(0.9-0.7)*RAND() -> 0.74796634
A8: 5 | B8: =I8*J8*G8*H8*K8 -> 346.55095 | C8: =0.15*9890*G8*SQRT(1-H8^2)*K8 -> 164.56356 | D8: 107.734 | E8: 296.99 | F8: 雷7板(朱庄)线185/6.14/34670.4/0.48/6% | G8: 0.40029269 | H8: 0.83235641 | I8: 34670.4 | J8: 0.06 | K8: 0.5 | L8: =0.7+(0.9-0.7)*RAND() -> 0.78269696
A9: 6 | B9: =I9*J9*G9*H9*K9 -> 307.88589 | C9: =0.15*9890*G9*SQRT(1-H9^2)*K9 -> 158.63145 | D9: 128.404 | E9: 247.643 | G9: 0.36518463 | H9: 0.81058245 | I9: 34670.4 | J9: 0.06 | K9: 0.5 | L9: =0.7+(0.9-0.7)*RAND() -> 0.7783208
A10: 7 | B10: =I10*J10*G10*H10*K10 -> 186.73015 | C10: =0.15*9890*G10*SQRT(1-H10^2)*K10 -> 111.92875 | D10: 216.816 | E10: 224.402 | G10: 0.23452269 | H10: 0.76550755 | I10: 34670.4 | J10: 0.06 | K10: 0.5 | L10: =0.7+(0.9-0.7)*RAND() -> 0.8068118
A11: 8 | B11: =I11*J11*G11*H11*K11 -> 613.29347 | C11: =0.15*9890*G11*SQRT(1-H11^2)*K11 -> 219.82154 | D11: 97.238 | E11: 329.169 | F11: 雷3板(坝直)线240/2.9/7615.4/2.58/42% | G11: 0.65992717 | H11: 0.89349521 | I11: 34670.4 | J11: 0.06 | K11: 0.5 | L11: =0.7+(0.9-0.7)*RAND() -> 0.81230281
A12: 9 | B12: =I12*J12*G12*H12*K12 -> 304.12433 | C12: =0.15*9890*G12*SQRT(1-H12^2)*K12 -> 128.80475 | D12: 84.89 | E12: 326.908 | G12: 0.34007283 | H12: 0.85980331 | I12: 34670.4 | J12: 0.06 | K12: 0.5 | L12: =0.7+(0.9-0.7)*RAND() -> 0.79454369
A13: 10 | B13: =I13*J13*G13*H13*K13 -> 334.75124 | C13: =0.15*9890*G13*SQRT(1-H13^2)*K13 -> 193.05014 | D13: 119.404 | E13: 405.872 | F13: 雷8板(北滩)线185/12.5/14951.6/0.59/14.1% | G13: 0.41059754 | H13: 0.77344435 | I13: 14951.6 | J13: 0.141 | K13: 0.5 | L13: =0.7+(0.9-0.7)*RAND() -> 0.80607221
A14: 11 | B14: =I14*J14*G14*H14*K14 -> 266.60706 | C14: =0.15*9890*G14*SQRT(1-H14^2)*K14 -> 143.56041 | D14: 74.934 | E14: 347.643 | G14: 0.31848203 | H14: 0.79416349 | I14: 14951.6 | J14: 0.141 | K14: 0.5 | L14: =0.7+(0.9-0.7)*RAND() -> 0.82607066
A15: 12 | B15: =I15*J15*G15*H15*K15 -> 125.27911 | C15: =0.15*9890*G15*SQRT(1-H15^2)*K15 -> 53.899677 | D15: 142.734 | E15: 427.643 | G15: 0.13930463 | H15: 0.85317145 | I15: 14951.6 | J15: 0.141 | K15: 0.5 | L15: =0.7+(0.9-0.7)*RAND() -> 0.88077022
A16: 13 | B16: =I16*J16*G16*H16*K16 -> 114.66605 | C16: =0.15*9890*G16*SQRT(1-H16^2)*K16 -> 54.955309 | D16: 179.816 | E16: 493.166 | G16: 0.1316158 | H16: 0.82651368 | I16: 14951.6 | J16: 0.141 | K16: 0.5 | L16: =0.7+(0.9-0.7)*RAND() -> 0.76010573
A17: 14 | B17: =I17*J17*G17*H17*K17 -> 1600.1051 | C17: =0.15*9890*G17*SQRT(1-H17^2)*K17 -> 156.78196 | D17: 133.581 | E17: 327.643 | F17: 雷2板(长胜)线240/6.98/18961.4/3.77/61.2% | G17: 0.34746045 | H17: 0.79369074 | I17: 18961.4 | J17: 0.612 | K17: 0.5 | L17: =0.7+(0.9-0.7)*RAND() -> 0.89863102
A18: 15 | B18: =I18*J18*G18*H18*K18 -> 1170.011 | C18: =0.15*9890*G18*SQRT(1-H18^2)*K18 -> 90.943999 | D18: 172.228 | E18: 317.225 | G18: 0.23599844 | H18: 0.85445459 | I18: 18961.4 | J18: 0.612 | K18: 0.5 | L18: =0.7+(0.9-0.7)*RAND() -> 0.80289609
A19: 16 | B19: =I19*J19*G19*H19*K19 -> 1121.3528 | C19: =0.15*9890*G19*SQRT(1-H19^2)*K19 -> 97.465846 | D19: 205.466 | E19: 323.813 | G19: 0.23370239 | H19: 0.8269653 | I19: 18961.4 | J19: 0.612 | K19: 0.5 | L19: =0.7+(0.9-0.7)*RAND() -> 0.84322089
A20: 17 | B20: =I20*J20*G20*H20*K20 -> 828.38949 | C20: =0.15*9890*G20*SQRT(1-H20^2)*K20 -> 84.722599 | D20: 195.11 | E20: 346.843 | G20: 0.18283872 | H20: 0.78086251 | I20: 18961.4 | J20: 0.612 | K20: 0.5 | L20: =0.7+(0.9-0.7)*RAND() -> 0.80088927
A21: 18 | B21: =I21*J21*G21*H21*K21 -> 0 | C21: =0.15*9890*G21*SQRT(1-H21^2)*K21 -> 0 | D21: 346.6 | E21: 344.366 | F21: - | G21: 0 | H21: 0.75161492 | I21: 0 | J21: 0 | K21: 0.5 | L21: =0.7+(0.9-0.7)*RAND() -> 0.88937781
A22: 19 | B22: =I22*J22*G22*H22*K22 -> 1656.7328 | C22: =0.15*9890*G22*SQRT(1-H22^2)*K22 -> 57.611785 | D22: 337.108 | E22: 359.299 | F22: 爪16板(谷营)线240/14.9/33600/7.41/93.8% | G22: 0.13071211 | H22: 0.80431197 | I22: 33600 | J22: 0.938 | K22: 0.5 | L22: =0.7+(0.9-0.7)*RAND() -> 0.79748289
A23: 20 | B23: =I23*J23*G23*H23*K23 -> 1538.4856 | C23: =0.15*9890*G23*SQRT(1-H23^2)*K23 -> 63.896517 | D23: 311.282 | E23: 355.375 | G23: 0.13020036 | H23: 0.74984089 | I23: 33600 | J23: 0.938 | K23: 0.5 | L23: =0.7+(0.9-0.7)*RAND() -> 0.87055065
A24: 21 | B24: =I24*J24*G24*H24*K24 -> 1651.2729 | C24: =0.15*9890*G24*SQRT(1-H24^2)*K24 -> 46.77942 | D24: 300.89 | E24: 369.691 | G24: 0.12230142 | H24: 0.85679165 | I24: 33600 | J24: 0.938 | K24: 0.5 | L24: =0.7+(0.9-0.7)*RAND() -> 0.88565131
A25: 22 | B25: =I25*J25*G25*H25*K25 -> 1590.3459 | C25: =0.15*9890*G25*SQRT(1-H25^2)*K25 -> 48.717801 | D25: 280.64 | E25: 354.96 | G25: 0.12041077 | H25: 0.83813533 | I25: 33600 | J25: 0.938 | K25: 0.5 | L25: =0.7+(0.9-0.7)*RAND() -> 0.72323638
A26: 23 | B26: =I26*J26*G26*H26*K26 -> 1284.651 | C26: =0.15*9890*G26*SQRT(1-H26^2)*K26 -> 55.146403 | D26: 244.463 | E26: 362.049 | G26: 0.11033205 | H26: 0.73887565 | I26: 33600 | J26: 0.938 | K26: 0.5 | L26: =0.7+(0.9-0.7)*RAND() -> 0.83671901
A27: 24 | B27: =I27*J27*G27*H27*K27 -> 1049.985 | C27: =0.15*9890*G27*SQRT(1-H27^2)*K27 -> 38.770089 | D27: 274.4 | E27: 372.143 | G27: 0.084685106 | H27: 0.78679929 | I27: 33600 | J27: 0.938 | K27: 0.5 | L27: =0.7+(0.9-0.7)*RAND() -> 0.88651643
A28: 25 | B28: =I28*J28*G28*H28*K28 -> 1004.8786 | C28: =0.15*9890*G28*SQRT(1-H28^2)*K28 -> 39.738763 | D28: 262.178 | E28: 390.876 | G28: 0.083285906 | H28: 0.76564939 | I28: 33600 | J28: 0.938 | K28: 0.5 | L28: =0.7+(0.9-0.7)*RAND() -> 0.83360561
A29: 26 | B29: =I29*J29*G29*H29*K29 -> 1078.5614 | C29: =0.15*9890*G29*SQRT(1-H29^2)*K29 -> 26.617664 | D29: 261.6 | E29: 413.832 | G29: 0.07728036 | H29: 0.88565302 | I29: 33600 | J29: 0.938 | K29: 0.5 | L29: =0.7+(0.9-0.7)*RAND() -> 0.77435998
A30: 27 | B30: =I30*J30*G30*H30*K30 -> 884.94929 | C30: =0.15*9890*G30*SQRT(1-H30^2)*K30 -> 26.986032 | D30: 313.345 | E30: 413.49 | G30: 0.066912345 | H30: 0.83926674 | I30: 33600 | J30: 0.938 | K30: 0.5 | L30: =0.7+(0.9-0.7)*RAND() -> 0.81800174
A31: 28 | B31: =I31*J31*G31*H31*K31 -> 886.50546 | C31: =0.15*9890*G31*SQRT(1-H31^2)*K31 -> 24.756021 | D31: 249.463 | E31: 459.049 | G31: 0.065411352 | H31: 0.86003508 | I31: 33600 | J31: 0.938 | K31: 0.5 | L31: =0.7+(0.9-0.7)*RAND() -> 0.70032374
A32: 29 | B32: =I32*J32*G32*H32*K32 -> 94.093614 | C32: =0.15*9890*G32*SQRT(1-H32^2)*K32 -> 4.4540612 | D32: 231.655 | E32: 571.72 | G32: 0.0084682131 | H32: 0.70510899 | I32: 33600 | J32: 0.938 | K32: 0.5 | L32: =0.7+(0.9-0.7)*RAND() -> 0.80413391
A33: 30 | B33: =I33*J33*G33*H33*K33 -> 555.28822 | C33: =0.15*9890*G33*SQRT(1-H33^2)*K33 -> 151.76981 | D33: 350.021 | E33: 359.299 | F33: 爪15板(中明)线240/5.8/12717.2/2.55/32.3% | G33: 0.33906343 | H33: 0.79739496 | I33: 12717.2 | J33: 0.323 | K33: 0.5 | L33: =0.7+(0.9-0.7)*RAND() -> 0.73250628
A34: 31 | B34: =I34*J34*G34*H34*K34 -> 441.81263 | C34: =0.15*9890*G34*SQRT(1-H34^2)*K34 -> 133.56949 | D34: 368.238 | E34: 366.038 | G34: 0.28053813 | H34: 0.76680018 | I34: 12717.2 | J34: 0.323 | K34: 0.5 | L34: =0.7+(0.9-0.7)*RAND() -> 0.81629687
A35: 32 | B35: =I35*J35*G35*H35*K35 -> 341.55402 | C35: =0.15*9890*G35*SQRT(1-H35^2)*K35 -> 98.593106 | D35: 338.021 | E35: 401.952 | G35: 0.21289365 | H35: 0.78114682 | I35: 12717.2 | J35: 0.323 | K35: 0.5 | L35: =0.7+(0.9-0.7)*RAND() -> 0.74628604
A36: 33 | B36: =I36*J36*G36*H36*K36 -> 261.71795 | C36: =0.15*9890*G36*SQRT(1-H36^2)*K36 -> 57.394281 | D36: 330.803 | E36: 431.256 | G36: 0.14908192 | H36: 0.85476064 | I36: 12717.2 | J36: 0.323 | K36: 0.5 | L36: =0.7+(0.9-0.7)*RAND() -> 0.70952939
A37: 34 | B37: =I37*J37*G37*H37*K37 -> 32.538722 | C37: =0.15*9890*G37*SQRT(1-H37^2)*K37 -> 6.9741489 | D37: 315.466 | E37: 444.96 | G37: 0.018422883 | H37: 0.85996124 | I37: 12717.2 | J37: 0.323 | K37: 0.5 | L37: =0.7+(0.9-0.7)*RAND() -> 0.88931054
A38: 35 | B38: =I38*J38*G38*H38*K38 -> 2043.9262 | C38: =0.15*9890*G38*SQRT(1-H38^2)*K38 -> 203.96799 | D38: 395.466 | E38: 362.643 | F38: 爪5板(马目)线240/5.9/24420/4.85/61.4% | G38: 0.38722714 | H38: 0.70406926 | I38: 24420 | J38: 0.614 | K38: 0.5 | L38: =0.7+(0.9-0.7)*RAND() -> 0.76545412
A39: 36 | B39: =I39*J39*G39*H39*K39 -> 2461.6153 | C39: =0.15*9890*G39*SQRT(1-H39^2)*K39 -> 129.59301 | D39: 396.6 | E39: 380.375 | G39: 0.37193784 | H39: 0.88280705 | I39: 24420 | J39: 0.614 | K39: 0.5 | L39: =0.7+(0.9-0.7)*RAND() -> 0.80674404
A40: 37 | B40: =I40*J40*G40*H40*K40 -> 1322.3633 | C40: =0.15*9890*G40*SQRT(1-H40^2)*K40 -> 121.63141 | D40: 399.803 | E40: 415.375 | G40: 0.24083502 | H40: 0.73239792 | I40: 24420 | J40: 0.614 | K40: 0.5 | L40: =0.7+(0.9-0.7)*RAND() -> 0.83619125
...

Sheet 基准点
A1: 马寨 | B1: 231.181 | C1: 559.093 | E1: =SQRT((B1-B2)^2+(C1-C2)^2) -> 186.3631 | F1: =E1/8.8 -> 21.177625
A2: 霍寨 | B2: 235.545 | C2: 372.781

Sheet Sheet4
A1: 0.60500937 | B1: 0.60969052 | C1: 0.58909566 | D1: 0.60417285 | E1: 0.59312975 | F1: 0.64378855 | G1: 0.72453662 | H1: 0.81533546 | I1: 0.76244036 | J1: 0.69408151 | K1: 0.62794628 | L1: 0.65766133 | M1: 0.63072955 | N1: 0.62586919 | O1: 0.60020857 | P1: 0.61225521 | Q1: 0.66196274 | R1: 0.81726871 | S1: 0.78518941 | T1: 0.80798813 | U1: 0.8084752 | V1: 0.73266956 | W1: 0.70220156 | X1: 0.63796167
A2: 0.81250758 | B2: 0.81879543 | C2: 0.79113976 | D2: 0.81139269 | E2: 0.79657632 | F2: 0.8646301 | G2: 0.97309488 | H2: 1.0950419 | I2: 1.0239996 | J2: 0.93217376 | K2: 0.8433243 | L2: 0.88320871 | M2: 0.8470366 | N2: 0.84050911 | O2: 0.80604941 | P2: 0.82223184 | Q2: 0.88899699 | R2: 1.0975762 | S2: 1.0545188 | T2: 1.0851556 | U2: 1.0858038 | V2: 0.9839879 | W2: 0.94305489 | X2: 0.85677356
A3: 0.81910674 | B3: 0.82544742 | C3: 0.79757083 | D3: 0.81799518 | E3: 0.80307899 | F3: 0.87171551 | G3: 0.98109433 | H3: 1.1040422 | I3: 1.0324142 | J3: 0.93981051 | K3: 0.85019293 | L3: 0.89036947 | M3: 0.85389831 | N3: 0.84731751 | O3: 0.81258036 | P3: 0.82890029 | Q3: 0.89622163 | R3: 1.1065072 | S3: 1.063135 | T3: 1.0940479 | U3: 1.0946927 | V3: 0.99203336 | W3: 0.95074541 | X3: 0.86374984
A4: 0.8512812 | B4: 0.85787616 | C4: 0.82891546 | D4: 0.85016253 | E4: 0.83472097 | F4: 0.90614207 | G4: 1.0199149 | H4: 1.1477227 | I4: 1.0732557 | J4: 0.97691995 | K4: 0.88364504 | L4: 0.92530585 | M4: 0.88738656 | N4: 0.88054642 | O4: 0.84445197 | P4: 0.86143088 | Q4: 0.93143767 | R4: 1.1500194 | S4: 1.1050466 | T4: 1.1372542 | U4: 1.1378989 | V4: 1.0311584 | W4: 0.98818228 | X4: 0.89772981
A5: 4.6645931 | B5: 4.7007832 | C5: 4.5422041 | D5: 4.6588357 | E5: 4.5748404 | F5: 4.9670939 | G5: 5.5608417 | H5: 5.5488362 | I5: 5.555678 | J5: 5.3550037 | K5: 4.8425072 | L5: 5.0698311 | M5: 4.861894 | N5: 4.824405 | O5: 4.6266986 | P5: 4.7199171 | Q5: 5.1039376 | R5: 5.5435531 | S5: 5.5499145 | T5: 5.5482839 | U5: 5.5477318 | V5: 5.5573109 | W5: 5.4156759 | X5: 4.9196372
A6: =SUM(A1:A5) -> 7.752498 | B6: =SUM(B1:B5) -> 7.8125927 | C6: =SUM(C1:C5) -> 7.5489258 | D6: =SUM(D1:D5) -> 7.742559 | E6: =SUM(E1:E5) -> 7.6023465 | F6: =SUM(F1:F5) -> 8.2533701 | G6: =SUM(G1:G5) -> 9.2594824 | H6: =SUM(H1:H5) -> 9.7109784 | ... X6: =SUM(X1:X5) -> 8.175852
